<?xml version="1.0"?>
<robot xmlns:xacro="http://www.ros.org/wiki/xacro" name="robot">

<xacro:include filename="inertial_macros.xacro" />

<material name="orange">
    <color rgba="1 0.3 0.1 1"/>
</material>
<material name="blue">
    <color rgba="0.2 0.2 1 1"/>
</material>
<material name="black">
    <color rgba="0 0 0 1"/>
</material>
<material name="red">
    <color rgba="1 0 0 1"/>
</material>
<material name="white">
    <color rgba="1 1 1 1"/>
</material>

<link name="base_link">
</link>

<!-- BASE_FOOTPRINT LINK -->
<joint name="base_footprint_joint" type="fixed">
  <parent link="base_link"/>
  <child link="base_footprint"/>
  <origin xyz="0 0 0" rpy="0 0 0"/>
</joint>

<link name="base_footprint">
</link>

<!-- CHASSIS -->
<joint name="chassis_joint" type="fixed">
    <parent link="base_link"/>
    <child link="chassis"/>
    <origin xyz="0 0 0"/>
</joint>

<link name="chassis">
    <visual>
        <origin xyz="0 0 0.075" rpy="0 0 0"/>
        <geometry>
            <box size="0.3 0.3 0.15"/>
        </geometry>
        <material name="white"/>
    </visual>
    <collision>
        <origin xyz="0 0 0.075" rpy="0 0 0"/>
        <geometry>
            <box size="0.3 0.3 0.15"/>
        </geometry>
    </collision>
    <xacro:inertial_box mass="0.5" x="0.3" y="0.3" z="0.15">
        <origin xyz="0 0 0.075" rpy="0 0 0"/>
    </xacro:inertial_box>
</link>

<gazebo reference="chassis">
    <material>Gazebo/White</material>
</gazebo>


<!-- LEFT WHEEL BACK-->
<joint name="back_left_wheel_joint" type="continuous">
    <parent link="base_link"/>
    <child link="back_left_wheel"/>
    <origin xyz="-0.075 0.17 0" rpy="-${pi/2} 0 0"/>
    <axis xyz="0 0 1"/>
</joint>

<link name="back_left_wheel">
    <visual>
        <geometry>
            <cylinder length="0.04" radius="0.05" />
        </geometry>
        <material name="blue"/>
    </visual>
    <collision>
        <geometry>
            <cylinder length="0.04" radius="0.05" />
        </geometry>
    </collision>
    <xacro:inertial_cylinder mass="0.1" length="0.04" radius="0.05">
        <origin xyz="0 0 0" rpy="0 0 0"/>
    </xacro:inertial_cylinder>
</link>

<!-- LEFT WHEEL FRONT-->
<joint name="front_left_wheel_joint" type="continuous">
    <parent link="base_link"/>
    <child link="front_left_wheel"/>
    <origin xyz="0.075 0.17 0" rpy="-${pi/2} 0 0"/>
    <axis xyz="0 0 1"/>
</joint>

<link name="front_left_wheel">
    <visual>
        <geometry>
            <cylinder length="0.04" radius="0.05" />
        </geometry>
        <material name="blue"/>
    </visual>
    <collision>
        <geometry>
            <cylinder length="0.04" radius="0.05" />
        </geometry>
    </collision>
    <xacro:inertial_cylinder mass="0.1" length="0.04" radius="0.05">
        <origin xyz="0 0 0" rpy="0 0 0"/>
    </xacro:inertial_cylinder>
</link>


<!-- RIGHT WHEEL BACK -->
<joint name="back_right_wheel_joint" type="continuous">
    <parent link="base_link"/>
    <child link="back_right_wheel"/>
    <origin xyz="-0.075 -0.17 0" rpy="${pi/2} 0 0"/>
    <axis xyz="0 0 -1"/>
</joint>

<link name="back_right_wheel">
    <visual>
        <geometry>
            <cylinder length="0.04" radius="0.05" />
        </geometry>
        <material name="blue"/>
    </visual>
    <collision>
        <geometry>
            <cylinder length="0.04" radius="0.05" />
        </geometry>
    </collision>
    <xacro:inertial_cylinder mass="0.1" length="0.04" radius="0.05">
        <origin xyz="0 0 0" rpy="0 0 0"/>
    </xacro:inertial_cylinder>
</link>

<!-- RIGHT WHEEL FRONT -->
<joint name="front_right_wheel_joint" type="continuous">
    <parent link="base_link"/>
    <child link="front_right_wheel"/>
    <origin xyz="0.075 -0.17 0" rpy="${pi/2} 0 0"/>
    <axis xyz="0 0 -1"/>
</joint>

<link name="front_right_wheel">
    <visual>
        <geometry>
            <cylinder length="0.04" radius="0.05" />
        </geometry>
        <material name="blue"/>
    </visual>
    <collision>
        <geometry>
            <cylinder length="0.04" radius="0.05" />
        </geometry>
    </collision>
    <xacro:inertial_cylinder mass="0.1" length="0.04" radius="0.05">
        <origin xyz="0 0 0" rpy="0 0 0"/>
    </xacro:inertial_cylinder>
</link>

<!-- ARM BASE 1-->
<joint name="arm_base1_joint" type="fixed">
    <parent link="chassis"/>
    <child link="arm_base1"/>
    <origin xyz="0 0 0" rpy="0 0 0"/> </joint>

<link name="arm_base1">
     <visual>
        <origin xyz="0.15 0 0.15" rpy="0 0 0"/>
        <geometry>
            <box size="0.05 0.05 0.3"/>
        </geometry>
        <material name="white"/>
    </visual>
    <collision>
        <origin xyz="0.15 0 0.15" rpy="0 0 0"/>
        <geometry>
            <box size="0.05 0.05 0.3"/>
        </geometry>
    </collision>
    <xacro:inertial_box mass="0.5" x="0.05" y="0.05" z="0.3">
        <origin xyz="0.15 0 0.15" rpy="0 0 0"/>
    </xacro:inertial_box>
</link>

<!-- ARM BASE 2-->
<joint name="arm_base2_joint" type="prismatic">
    <parent link="arm_base1"/>
    <child link="arm_base2"/>
    <origin xyz="0.2 0 0.15" rpy="0 0 0"/> 
    <axis xyz="0 0 1"/>
    <limit lower="-0.125" upper="0.125" effort="100" velocity="1.0"/></joint>

<link name="arm_base2">
     <visual>
        <origin xyz="0 0 0" rpy="0 0 0"/>
        <geometry>
            <box size="0.05 0.52 0.05"/>
            
            
        </geometry>
        <material name="white"/>
    </visual>
    <collision>
        <origin xyz="0 0 0" rpy="0 0 0"/>
        <geometry>
            <box size="0.05 0.52 0.05"/>
        </geometry>
    </collision>
    <xacro:inertial_box mass="0.5" x="0.05" y="0.52" z="0.05">
        <origin xyz="0 0 0" rpy="0 0 0"/>
    </xacro:inertial_box>
</link>


<!-- ARM -->
<!-- <joint name="arm_joint" type="revolute">
    <parent link="arm_base"/>
    <child link="arm_link"/>
    <origin xyz="0 0 0.05" rpy="0 0 0"/>
    <axis xyz="0 1 0"/> <limit lower="-1.57" upper="1.57" effort="10" velocity="1.0"/>
</joint>

<link name="arm_link">
    <visual>
        <origin xyz="0.1 0 0" rpy="0 0 0"/>
        <geometry>
            <box size="0.2 0.04 0.04"/>
        </geometry>
        <material name="white"/>
    </visual>
</link> -->


<!-- CASTER WHEEL -->
<!-- <joint name="caster_wheel_joint" type="fixed">
    <parent link="chassis"/>
    <child link="caster_wheel"/>
    <origin xyz="0.24 0 0" rpy="0 0 0"/>
</joint>

<link name="caster_wheel">
    <visual>
        <geometry>
            <sphere radius="0.05" />
        </geometry>
        <material name="black"/>
    </visual>
    <collision>
        <geometry>
            <sphere radius="0.05" />
        </geometry>
    </collision>
    <xacro:inertial_sphere mass="0.1" radius="0.05">
            <origin xyz="0 0 0" rpy="0 0 0"/>
    </xacro:inertial_sphere>
</link>

<gazebo reference="caster_wheel">
    <material>Gazebo/Black</material>
    <mu1 value="0.001"/>
    <mu2 value="0.001"/>
</gazebo> -->


</robot>